[ 2019-01-20 16:40:35 ] 
Traceback (most recent call last):
  File "alexa.py", line 55, in <module>
    detector.start(detected_callback=lambda: main.main(p,detector),sleep_time=0.03)
  File "/opt/MessyPi/yuyin/alexa/func_alexa/snowboydecoder.py", line 221, in start
    callback()
  File "alexa.py", line 55, in <lambda>
    detector.start(detected_callback=lambda: main.main(p,detector),sleep_time=0.03)
  File "/opt/MessyPi/yuyin/alexa/func_messy/main.py", line 63, in main
    volume.play_prompt(alexa_said)
  File "/opt/MessyPi/yuyin/alexa/func_messy/volume.py", line 96, in play_prompt
    pygame.mixer.music.play(loop=0)
TypeError: 'loop' is an invalid keyword argument for this function

[ 2019-01-20 17:10:39 ] 
Traceback (most recent call last):
  File "alexa.py", line 55, in <module>
    detector.start(detected_callback=lambda: main.main(p,detector),sleep_time=0.03)
  File "/opt/MessyPi/yuyin/alexa/func_alexa/snowboydecoder.py", line 221, in start
    callback()
  File "alexa.py", line 55, in <lambda>
    detector.start(detected_callback=lambda: main.main(p,detector),sleep_time=0.03)
  File "/opt/MessyPi/yuyin/alexa/func_messy/main.py", line 40, in main
    volume_in = volume.volume(p)
  File "/opt/MessyPi/yuyin/alexa/func_messy/volume.py", line 54, in volume
    temp_in = volume_hasbeen()
  File "/opt/MessyPi/yuyin/alexa/func_messy/volume.py", line 35, in volume_hasbeen
    data = stream.read(CHUNK)
UnboundLocalError: local variable 'stream' referenced before assignment

[ 2019-01-20 17:12:08 ] 
Traceback (most recent call last):
  File "alexa.py", line 55, in <module>
    detector.start(detected_callback=lambda: main.main(p,detector),sleep_time=0.03)
  File "/opt/MessyPi/yuyin/alexa/func_alexa/snowboydecoder.py", line 221, in start
    callback()
  File "alexa.py", line 55, in <lambda>
    detector.start(detected_callback=lambda: main.main(p,detector),sleep_time=0.03)
  File "/opt/MessyPi/yuyin/alexa/func_messy/main.py", line 40, in main
    volume_in = volume.volume(p)
  File "/opt/MessyPi/yuyin/alexa/func_messy/volume.py", line 54, in volume
    temp_in = volume_hasbeen()
  File "/opt/MessyPi/yuyin/alexa/func_messy/volume.py", line 34, in volume_hasbeen
    stream = p.open(format=FORMAT,
NameError: name 'p' is not defined

[ 2019-01-20 17:12:38 ] 
Traceback (most recent call last):
  File "alexa.py", line 55, in <module>
    detector.start(detected_callback=lambda: main.main(p,detector),sleep_time=0.03)
  File "/opt/MessyPi/yuyin/alexa/func_alexa/snowboydecoder.py", line 221, in start
    callback()
  File "alexa.py", line 55, in <lambda>
    detector.start(detected_callback=lambda: main.main(p,detector),sleep_time=0.03)
  File "/opt/MessyPi/yuyin/alexa/func_messy/main.py", line 40, in main
    volume_in = volume.volume(p)
  File "/opt/MessyPi/yuyin/alexa/func_messy/volume.py", line 54, in volume
    temp_in = volume_hasbeen(p)
  File "/opt/MessyPi/yuyin/alexa/func_messy/volume.py", line 41, in volume_hasbeen
    frames.append(data)
NameError: name 'frames' is not defined

[ 2019-01-20 17:13:38 ] 
Traceback (most recent call last):
  File "alexa.py", line 55, in <module>
    detector.start(detected_callback=lambda: main.main(p,detector),sleep_time=0.03)
  File "/opt/MessyPi/yuyin/alexa/func_alexa/snowboydecoder.py", line 221, in start
    callback()
  File "alexa.py", line 55, in <lambda>
    detector.start(detected_callback=lambda: main.main(p,detector),sleep_time=0.03)
  File "/opt/MessyPi/yuyin/alexa/func_messy/main.py", line 40, in main
    volume_in = volume.volume(p)
  File "/opt/MessyPi/yuyin/alexa/func_messy/volume.py", line 63, in volume
    if temp > FAZHI:
NameError: name 'temp' is not defined

[ 2019-01-20 17:22:48 ] 
Traceback (most recent call last):
  File "alexa.py", line 55, in <module>
    detector.start(detected_callback=lambda: main.main(p,detector),sleep_time=0.03)
  File "/opt/MessyPi/yuyin/alexa/func_alexa/snowboydecoder.py", line 221, in start
    callback()
  File "alexa.py", line 55, in <lambda>
    detector.start(detected_callback=lambda: main.main(p,detector),sleep_time=0.03)
  File "/opt/MessyPi/yuyin/alexa/func_messy/main.py", line 39, in main
    volume_in = volume.volume(p)
  File "/opt/MessyPi/yuyin/alexa/func_messy/volume.py", line 51, in volume
    temp_in = volume_hasbeen(p,frames)
  File "/opt/MessyPi/yuyin/alexa/func_messy/volume.py", line 39, in volume_hasbeen
    audio_data = np.fromstring(data, dtype=np.short)
NameError: name 'data' is not defined

[ 2019-01-20 17:23:35 ] 
Traceback (most recent call last):
  File "alexa.py", line 55, in <module>
    detector.start(detected_callback=lambda: main.main(p,detector),sleep_time=0.03)
  File "/opt/MessyPi/yuyin/alexa/func_alexa/snowboydecoder.py", line 221, in start
    callback()
  File "alexa.py", line 55, in <lambda>
    detector.start(detected_callback=lambda: main.main(p,detector),sleep_time=0.03)
  File "/opt/MessyPi/yuyin/alexa/func_messy/main.py", line 39, in main
    volume_in = volume.volume(p)
  File "/opt/MessyPi/yuyin/alexa/func_messy/volume.py", line 53, in volume
    temp_in = volume_hasbeen(p,frames)[0]
  File "/opt/MessyPi/yuyin/alexa/func_messy/volume.py", line 40, in volume_hasbeen
    data = temp_in_stream.read(CHUNK)
NameError: name 'temp_in_stream' is not defined

[ 2019-01-20 17:24:14 ] 
Traceback (most recent call last):
  File "alexa.py", line 55, in <module>
    detector.start(detected_callback=lambda: main.main(p,detector),sleep_time=0.03)
  File "/opt/MessyPi/yuyin/alexa/func_alexa/snowboydecoder.py", line 221, in start
    callback()
  File "alexa.py", line 55, in <lambda>
    detector.start(detected_callback=lambda: main.main(p,detector),sleep_time=0.03)
  File "/opt/MessyPi/yuyin/alexa/func_messy/main.py", line 39, in main
    volume_in = volume.volume(p)
  File "/opt/MessyPi/yuyin/alexa/func_messy/volume.py", line 53, in volume
    temp_in = volume_hasbeen(p,frames)[0]
  File "/opt/MessyPi/yuyin/alexa/func_messy/volume.py", line 38, in volume_hasbeen
    frames_per_buffer=CHUNK)
  File "/usr/local/lib/python3.5/dist-packages/pyaudio.py", line 750, in open
    stream = Stream(self, *args, **kwargs)
  File "/usr/local/lib/python3.5/dist-packages/pyaudio.py", line 441, in __init__
    self._stream = pa.open(**arguments)
OSError: [Errno -9985] Device unavailable

[ 2019-01-20 17:26:32 ] 
Traceback (most recent call last):
  File "alexa.py", line 55, in <module>
    detector.start(detected_callback=lambda: main.main(p,detector),sleep_time=0.03)
  File "/opt/MessyPi/yuyin/alexa/func_alexa/snowboydecoder.py", line 176, in start
    stream_callback=audio_callback)
  File "/usr/local/lib/python3.5/dist-packages/pyaudio.py", line 750, in open
    stream = Stream(self, *args, **kwargs)
  File "/usr/local/lib/python3.5/dist-packages/pyaudio.py", line 441, in __init__
    self._stream = pa.open(**arguments)
OSError: [Errno -9985] Device unavailable

[ 2019-01-20 17:27:46 ] 
Traceback (most recent call last):
  File "alexa.py", line 55, in <module>
    detector.start(detected_callback=lambda: main.main(p,detector),sleep_time=0.03)
  File "/opt/MessyPi/yuyin/alexa/func_alexa/snowboydecoder.py", line 176, in start
    stream_callback=audio_callback)
  File "/usr/local/lib/python3.5/dist-packages/pyaudio.py", line 750, in open
    stream = Stream(self, *args, **kwargs)
  File "/usr/local/lib/python3.5/dist-packages/pyaudio.py", line 441, in __init__
    self._stream = pa.open(**arguments)
OSError: [Errno -9985] Device unavailable

[ 2019-01-20 17:29:12 ] 
Traceback (most recent call last):
  File "alexa.py", line 55, in <module>
    detector.start(detected_callback=lambda: main.main(p,detector),sleep_time=0.03)
  File "/opt/MessyPi/yuyin/alexa/func_alexa/snowboydecoder.py", line 176, in start
    stream_callback=audio_callback)
  File "/usr/local/lib/python3.5/dist-packages/pyaudio.py", line 750, in open
    stream = Stream(self, *args, **kwargs)
  File "/usr/local/lib/python3.5/dist-packages/pyaudio.py", line 441, in __init__
    self._stream = pa.open(**arguments)
OSError: [Errno -9985] Device unavailable

[ 2019-01-20 17:30:27 ] 
Traceback (most recent call last):
  File "alexa.py", line 55, in <module>
    detector.start(detected_callback=lambda: main.main(p,detector),sleep_time=0.03)
  File "/opt/MessyPi/yuyin/alexa/func_alexa/snowboydecoder.py", line 176, in start
    stream_callback=audio_callback)
  File "/usr/local/lib/python3.5/dist-packages/pyaudio.py", line 750, in open
    stream = Stream(self, *args, **kwargs)
  File "/usr/local/lib/python3.5/dist-packages/pyaudio.py", line 441, in __init__
    self._stream = pa.open(**arguments)
OSError: [Errno -9985] Device unavailable

[ 2019-01-20 17:33:04 ] 
Traceback (most recent call last):
  File "alexa.py", line 55, in <module>
    detector.start(detected_callback=lambda: main.main(p,detector),sleep_time=0.03)
  File "/opt/MessyPi/yuyin/alexa/func_alexa/snowboydecoder.py", line 176, in start
    stream_callback=audio_callback)
  File "/usr/local/lib/python3.5/dist-packages/pyaudio.py", line 750, in open
    stream = Stream(self, *args, **kwargs)
  File "/usr/local/lib/python3.5/dist-packages/pyaudio.py", line 441, in __init__
    self._stream = pa.open(**arguments)
OSError: [Errno -9985] Device unavailable

[ 2019-01-20 17:33:38 ] 
Traceback (most recent call last):
  File "alexa.py", line 55, in <module>
    detector.start(detected_callback=lambda: main.main(p,detector),sleep_time=0.03)
  File "/opt/MessyPi/yuyin/alexa/func_alexa/snowboydecoder.py", line 176, in start
    stream_callback=audio_callback)
  File "/usr/local/lib/python3.5/dist-packages/pyaudio.py", line 750, in open
    stream = Stream(self, *args, **kwargs)
  File "/usr/local/lib/python3.5/dist-packages/pyaudio.py", line 441, in __init__
    self._stream = pa.open(**arguments)
OSError: [Errno -9985] Device unavailable

[ 2019-01-20 17:37:13 ] 
Traceback (most recent call last):
  File "alexa.py", line 55, in <module>
    detector.start(detected_callback=lambda: main.main(p,detector),sleep_time=0.03)
  File "/opt/MessyPi/yuyin/alexa/func_alexa/snowboydecoder.py", line 176, in start
    stream_callback=audio_callback)
  File "/usr/local/lib/python3.5/dist-packages/pyaudio.py", line 750, in open
    stream = Stream(self, *args, **kwargs)
  File "/usr/local/lib/python3.5/dist-packages/pyaudio.py", line 441, in __init__
    self._stream = pa.open(**arguments)
OSError: [Errno -9985] Device unavailable

[ 2019-01-20 17:38:31 ] 
Traceback (most recent call last):
  File "alexa.py", line 55, in <module>
    detector.start(detected_callback=lambda: main.main(p,detector),sleep_time=0.03)
  File "/opt/MessyPi/yuyin/alexa/func_alexa/snowboydecoder.py", line 176, in start
    stream_callback=audio_callback)
  File "/usr/local/lib/python3.5/dist-packages/pyaudio.py", line 750, in open
    stream = Stream(self, *args, **kwargs)
  File "/usr/local/lib/python3.5/dist-packages/pyaudio.py", line 441, in __init__
    self._stream = pa.open(**arguments)
OSError: [Errno -9985] Device unavailable

[ 2019-01-20 17:41:00 ] 
Traceback (most recent call last):
  File "alexa.py", line 55, in <module>
    detector.start(detected_callback=lambda: main.main(p,detector),sleep_time=0.03)
  File "/opt/MessyPi/yuyin/alexa/func_alexa/snowboydecoder.py", line 176, in start
    stream_callback=audio_callback)
  File "/usr/local/lib/python3.5/dist-packages/pyaudio.py", line 750, in open
    stream = Stream(self, *args, **kwargs)
  File "/usr/local/lib/python3.5/dist-packages/pyaudio.py", line 441, in __init__
    self._stream = pa.open(**arguments)
OSError: [Errno -9985] Device unavailable

[ 2019-01-20 17:49:36 ] 
Traceback (most recent call last):
  File "alexa.py", line 55, in <module>
    detector.start(detected_callback=lambda: main.main(p,detector),sleep_time=0.03)
  File "/opt/MessyPi/yuyin/alexa/func_alexa/snowboydecoder.py", line 221, in start
    callback()
  File "alexa.py", line 55, in <lambda>
    detector.start(detected_callback=lambda: main.main(p,detector),sleep_time=0.03)
  File "/opt/MessyPi/yuyin/alexa/func_messy/main.py", line 39, in main
    volume_in = volume.volume(p)
  File "/opt/MessyPi/yuyin/alexa/func_messy/volume.py", line 78, in volume
    volume.play_prompt_not_loop(play_ding)
AttributeError: 'function' object has no attribute 'play_prompt_not_loop'

[ 2019-01-20 17:50:09 ] 
Traceback (most recent call last):
  File "alexa.py", line 55, in <module>
    detector.start(detected_callback=lambda: main.main(p,detector),sleep_time=0.03)
  File "/opt/MessyPi/yuyin/alexa/func_alexa/snowboydecoder.py", line 221, in start
    callback()
  File "alexa.py", line 55, in <lambda>
    detector.start(detected_callback=lambda: main.main(p,detector),sleep_time=0.03)
  File "/opt/MessyPi/yuyin/alexa/func_messy/main.py", line 39, in main
    volume_in = volume.volume(p)
  File "/opt/MessyPi/yuyin/alexa/func_messy/volume.py", line 81, in volume
    data = stream.read(CHUNK)
  File "/usr/local/lib/python3.5/dist-packages/pyaudio.py", line 608, in read
    return pa.read_stream(self._stream, num_frames, exception_on_overflow)
OSError: [Errno -9981] Input overflowed

[ 2019-01-20 17:51:32 ] 
Traceback (most recent call last):
  File "alexa.py", line 55, in <module>
    detector.start(detected_callback=lambda: main.main(p,detector),sleep_time=0.03)
  File "/opt/MessyPi/yuyin/alexa/func_alexa/snowboydecoder.py", line 176, in start
    stream_callback=audio_callback)
  File "/usr/local/lib/python3.5/dist-packages/pyaudio.py", line 750, in open
    stream = Stream(self, *args, **kwargs)
  File "/usr/local/lib/python3.5/dist-packages/pyaudio.py", line 441, in __init__
    self._stream = pa.open(**arguments)
OSError: [Errno -9985] Device unavailable

[ 2019-01-20 17:55:55 ] 
Traceback (most recent call last):
  File "alexa.py", line 55, in <module>
    detector.start(detected_callback=lambda: main.main(p,detector),sleep_time=0.03)
  File "/opt/MessyPi/yuyin/alexa/func_alexa/snowboydecoder.py", line 176, in start
    stream_callback=audio_callback)
  File "/usr/local/lib/python3.5/dist-packages/pyaudio.py", line 750, in open
    stream = Stream(self, *args, **kwargs)
  File "/usr/local/lib/python3.5/dist-packages/pyaudio.py", line 441, in __init__
    self._stream = pa.open(**arguments)
OSError: [Errno -9985] Device unavailable

[ 2019-01-20 17:58:25 ] 
Traceback (most recent call last):
  File "alexa.py", line 55, in <module>
    detector.start(detected_callback=lambda: main.main(p,detector),sleep_time=0.03)
  File "/opt/MessyPi/yuyin/alexa/func_alexa/snowboydecoder.py", line 176, in start
    stream_callback=audio_callback)
  File "/usr/local/lib/python3.5/dist-packages/pyaudio.py", line 750, in open
    stream = Stream(self, *args, **kwargs)
  File "/usr/local/lib/python3.5/dist-packages/pyaudio.py", line 441, in __init__
    self._stream = pa.open(**arguments)
OSError: [Errno -9985] Device unavailable

[ 2019-01-20 18:10:36 ] 
Traceback (most recent call last):
  File "alexa.py", line 55, in <module>
    detector.start(detected_callback=lambda: main.main(p,detector),sleep_time=0.03)
  File "/opt/MessyPi/yuyin/alexa/func_alexa/snowboydecoder.py", line 176, in start
    stream_callback=audio_callback)
  File "/usr/local/lib/python3.5/dist-packages/pyaudio.py", line 750, in open
    stream = Stream(self, *args, **kwargs)
  File "/usr/local/lib/python3.5/dist-packages/pyaudio.py", line 441, in __init__
    self._stream = pa.open(**arguments)
OSError: [Errno -9985] Device unavailable

[ 2019-01-20 18:12:58 ] 
Traceback (most recent call last):
  File "alexa.py", line 55, in <module>
    detector.start(detected_callback=lambda: main.main(p,detector),sleep_time=0.03)
  File "/opt/MessyPi/yuyin/alexa/func_alexa/snowboydecoder.py", line 176, in start
    stream_callback=audio_callback)
  File "/usr/local/lib/python3.5/dist-packages/pyaudio.py", line 750, in open
    stream = Stream(self, *args, **kwargs)
  File "/usr/local/lib/python3.5/dist-packages/pyaudio.py", line 441, in __init__
    self._stream = pa.open(**arguments)
OSError: [Errno -9985] Device unavailable

[ 2019-01-20 18:27:03 ] 
Traceback (most recent call last):
  File "alexa.py", line 37, in <module>
    pygame.mixer.init(frequency=15500, size=-16, channels=4)
pygame.error: No available audio device

[ 2019-01-20 18:27:03 ] 
Traceback (most recent call last):
  File "alexa.py", line 37, in <module>
    pygame.mixer.init(frequency=15500, size=-16, channels=4)
pygame.error: No available audio device

During handling of the above exception, another exception occurred:

Traceback (most recent call last):
  File "alexa.py", line 42, in <module>
    exit()
  File "/usr/lib/python3.5/_sitebuiltins.py", line 26, in __call__
    raise SystemExit(code)
SystemExit: None

[ 2019-01-20 18:28:44 ] 
Traceback (most recent call last):
  File "alexa.py", line 55, in <module>
    detector.start(detected_callback=lambda: main.main(p,detector),sleep_time=0.03)
  File "/opt/MessyPi/yuyin/alexa/func_alexa/snowboydecoder.py", line 176, in start
    stream_callback=audio_callback)
  File "/usr/local/lib/python3.5/dist-packages/pyaudio.py", line 750, in open
    stream = Stream(self, *args, **kwargs)
  File "/usr/local/lib/python3.5/dist-packages/pyaudio.py", line 441, in __init__
    self._stream = pa.open(**arguments)
OSError: [Errno -9985] Device unavailable

[ 2019-01-20 18:42:01 ] 
Traceback (most recent call last):
  File "alexa.py", line 37, in <module>
    pygame.mixer.init(frequency=15500, size=-16, channels=4)
pygame.error: No available audio device

[ 2019-01-20 18:42:01 ] 
Traceback (most recent call last):
  File "alexa.py", line 37, in <module>
    pygame.mixer.init(frequency=15500, size=-16, channels=4)
pygame.error: No available audio device

During handling of the above exception, another exception occurred:

Traceback (most recent call last):
  File "alexa.py", line 42, in <module>
    exit()
  File "/usr/lib/python3.5/_sitebuiltins.py", line 26, in __call__
    raise SystemExit(code)
SystemExit: None

[ 2019-01-20 18:42:56 ] 
Traceback (most recent call last):
  File "alexa.py", line 55, in <module>
    detector.start(detected_callback=lambda: main.main(p,detector),sleep_time=0.03)
  File "/opt/MessyPi/yuyin/alexa/func_alexa/snowboydecoder.py", line 176, in start
    stream_callback=audio_callback)
  File "/usr/local/lib/python3.5/dist-packages/pyaudio.py", line 750, in open
    stream = Stream(self, *args, **kwargs)
  File "/usr/local/lib/python3.5/dist-packages/pyaudio.py", line 441, in __init__
    self._stream = pa.open(**arguments)
OSError: [Errno -9985] Device unavailable

[ 2019-01-20 18:44:23 ] 
Traceback (most recent call last):
  File "alexa.py", line 55, in <module>
    detector.start(detected_callback=lambda: main.main(p,detector),sleep_time=0.03)
  File "/opt/MessyPi/yuyin/alexa/func_alexa/snowboydecoder.py", line 176, in start
    stream_callback=audio_callback)
  File "/usr/local/lib/python3.5/dist-packages/pyaudio.py", line 750, in open
    stream = Stream(self, *args, **kwargs)
  File "/usr/local/lib/python3.5/dist-packages/pyaudio.py", line 441, in __init__
    self._stream = pa.open(**arguments)
OSError: [Errno -9985] Device unavailable

[ 2019-01-20 18:51:09 ] 
Traceback (most recent call last):
  File "alexa.py", line 55, in <module>
    detector.start(detected_callback=lambda: main.main(p,detector),sleep_time=0.03)
  File "/opt/MessyPi/yuyin/alexa/func_alexa/snowboydecoder.py", line 176, in start
    stream_callback=audio_callback)
  File "/usr/local/lib/python3.5/dist-packages/pyaudio.py", line 750, in open
    stream = Stream(self, *args, **kwargs)
  File "/usr/local/lib/python3.5/dist-packages/pyaudio.py", line 441, in __init__
    self._stream = pa.open(**arguments)
OSError: [Errno -9985] Device unavailable

[ 2019-01-20 19:28:27 ] 
Traceback (most recent call last):
  File "alexa.py", line 55, in <module>
    detector.start(detected_callback=lambda: main.main(p,detector),sleep_time=0.03)
  File "/opt/MessyPi/yuyin/alexa/func_alexa/snowboydecoder.py", line 176, in start
    stream_callback=audio_callback)
  File "/usr/local/lib/python3.5/dist-packages/pyaudio.py", line 750, in open
    stream = Stream(self, *args, **kwargs)
  File "/usr/local/lib/python3.5/dist-packages/pyaudio.py", line 441, in __init__
    self._stream = pa.open(**arguments)
OSError: [Errno -9985] Device unavailable

[ 2019-01-20 19:42:17 ] 
Traceback (most recent call last):
  File "alexa.py", line 55, in <module>
    detector.start(detected_callback=lambda: main.main(p,detector),sleep_time=0.03)
  File "/opt/MessyPi/yuyin/alexa/func_alexa/snowboydecoder.py", line 176, in start
    stream_callback=audio_callback)
  File "/usr/local/lib/python3.5/dist-packages/pyaudio.py", line 750, in open
    stream = Stream(self, *args, **kwargs)
  File "/usr/local/lib/python3.5/dist-packages/pyaudio.py", line 441, in __init__
    self._stream = pa.open(**arguments)
OSError: [Errno -9985] Device unavailable

[ 2019-01-20 19:47:40 ] 
Traceback (most recent call last):
  File "alexa.py", line 55, in <module>
    detector.start(detected_callback=lambda: main.main(p,detector),sleep_time=0.03)
  File "/opt/MessyPi/yuyin/alexa/func_alexa/snowboydecoder.py", line 221, in start
    callback()
  File "alexa.py", line 55, in <lambda>
    detector.start(detected_callback=lambda: main.main(p,detector),sleep_time=0.03)
  File "/opt/MessyPi/yuyin/alexa/func_messy/main.py", line 46, in main
    play_audio_file(none_prompt)
  File "/opt/MessyPi/yuyin/alexa/func_alexa/snowboydecoder.py", line 71, in play_audio_file
    rate=ding_wav.getframerate(), input=False, output=True)
  File "/usr/local/lib/python3.5/dist-packages/pyaudio.py", line 750, in open
    stream = Stream(self, *args, **kwargs)
  File "/usr/local/lib/python3.5/dist-packages/pyaudio.py", line 441, in __init__
    self._stream = pa.open(**arguments)
OSError: [Errno -9985] Device unavailable

[ 2019-01-20 19:50:37 ] 
Traceback (most recent call last):
  File "alexa.py", line 55, in <module>
    detector.start(detected_callback=lambda: main.main(p,detector),sleep_time=0.03)
  File "/opt/MessyPi/yuyin/alexa/func_alexa/snowboydecoder.py", line 176, in start
    stream_callback=audio_callback)
  File "/usr/local/lib/python3.5/dist-packages/pyaudio.py", line 750, in open
    stream = Stream(self, *args, **kwargs)
  File "/usr/local/lib/python3.5/dist-packages/pyaudio.py", line 441, in __init__
    self._stream = pa.open(**arguments)
OSError: [Errno -9985] Device unavailable

[ 2019-01-20 19:58:17 ] 
Traceback (most recent call last):
  File "alexa.py", line 55, in <module>
    detector.start(detected_callback=lambda: main.main(p,detector),sleep_time=0.03)
  File "/opt/MessyPi/yuyin/alexa/func_alexa/snowboydecoder.py", line 176, in start
    stream_callback=audio_callback)
  File "/usr/local/lib/python3.5/dist-packages/pyaudio.py", line 750, in open
    stream = Stream(self, *args, **kwargs)
  File "/usr/local/lib/python3.5/dist-packages/pyaudio.py", line 441, in __init__
    self._stream = pa.open(**arguments)
OSError: [Errno -9985] Device unavailable

[ 2019-01-20 20:00:08 ] 
Traceback (most recent call last):
  File "alexa.py", line 55, in <module>
    detector.start(detected_callback=lambda: main.main(p,detector),sleep_time=0.03)
  File "/opt/MessyPi/yuyin/alexa/func_alexa/snowboydecoder.py", line 176, in start
    stream_callback=audio_callback)
  File "/usr/local/lib/python3.5/dist-packages/pyaudio.py", line 750, in open
    stream = Stream(self, *args, **kwargs)
  File "/usr/local/lib/python3.5/dist-packages/pyaudio.py", line 441, in __init__
    self._stream = pa.open(**arguments)
OSError: [Errno -9985] Device unavailable

[ 2019-01-20 20:10:49 ] 
Traceback (most recent call last):
  File "alexa.py", line 55, in <module>
    detector.start(detected_callback=lambda: main.main(p,detector),sleep_time=0.03)
  File "/opt/MessyPi/yuyin/alexa/func_alexa/snowboydecoder.py", line 176, in start
    stream_callback=audio_callback)
  File "/usr/local/lib/python3.5/dist-packages/pyaudio.py", line 750, in open
    stream = Stream(self, *args, **kwargs)
  File "/usr/local/lib/python3.5/dist-packages/pyaudio.py", line 441, in __init__
    self._stream = pa.open(**arguments)
OSError: [Errno -9985] Device unavailable

[ 2019-01-20 20:11:52 ] 
Traceback (most recent call last):
  File "alexa.py", line 55, in <module>
    detector.start(detected_callback=lambda: main.main(p,detector),sleep_time=0.03)
  File "/opt/MessyPi/yuyin/alexa/func_alexa/snowboydecoder.py", line 176, in start
    stream_callback=audio_callback)
  File "/usr/local/lib/python3.5/dist-packages/pyaudio.py", line 750, in open
    stream = Stream(self, *args, **kwargs)
  File "/usr/local/lib/python3.5/dist-packages/pyaudio.py", line 441, in __init__
    self._stream = pa.open(**arguments)
OSError: [Errno -9985] Device unavailable

[ 2019-01-20 20:12:24 ] 
Traceback (most recent call last):
  File "alexa.py", line 55, in <module>
    detector.start(detected_callback=lambda: main.main(p,detector),sleep_time=0.03)
  File "/opt/MessyPi/yuyin/alexa/func_alexa/snowboydecoder.py", line 176, in start
    stream_callback=audio_callback)
  File "/usr/local/lib/python3.5/dist-packages/pyaudio.py", line 750, in open
    stream = Stream(self, *args, **kwargs)
  File "/usr/local/lib/python3.5/dist-packages/pyaudio.py", line 441, in __init__
    self._stream = pa.open(**arguments)
OSError: [Errno -9985] Device unavailable

[ 2019-01-20 20:14:52 ] 
Traceback (most recent call last):
  File "alexa.py", line 55, in <module>
    detector.start(detected_callback=lambda: main.main(p,detector),sleep_time=0.03)
  File "/opt/MessyPi/yuyin/alexa/func_alexa/snowboydecoder.py", line 176, in start
    stream_callback=audio_callback)
  File "/usr/local/lib/python3.5/dist-packages/pyaudio.py", line 750, in open
    stream = Stream(self, *args, **kwargs)
  File "/usr/local/lib/python3.5/dist-packages/pyaudio.py", line 441, in __init__
    self._stream = pa.open(**arguments)
OSError: [Errno -9985] Device unavailable

[ 2019-01-20 20:22:26 ] 
Traceback (most recent call last):
  File "alexa.py", line 55, in <module>
    detector.start(detected_callback=lambda: main.main(p,detector),sleep_time=0.03)
  File "/opt/MessyPi/yuyin/alexa/func_alexa/snowboydecoder.py", line 176, in start
    stream_callback=audio_callback)
  File "/usr/local/lib/python3.5/dist-packages/pyaudio.py", line 750, in open
    stream = Stream(self, *args, **kwargs)
  File "/usr/local/lib/python3.5/dist-packages/pyaudio.py", line 441, in __init__
    self._stream = pa.open(**arguments)
OSError: [Errno -9985] Device unavailable

[ 2019-01-20 20:25:10 ] 
Traceback (most recent call last):
  File "alexa.py", line 55, in <module>
    detector.start(detected_callback=lambda: main.main(p,detector),sleep_time=0.03)
  File "/opt/MessyPi/yuyin/alexa/func_alexa/snowboydecoder.py", line 176, in start
    stream_callback=audio_callback)
  File "/usr/local/lib/python3.5/dist-packages/pyaudio.py", line 750, in open
    stream = Stream(self, *args, **kwargs)
  File "/usr/local/lib/python3.5/dist-packages/pyaudio.py", line 441, in __init__
    self._stream = pa.open(**arguments)
OSError: [Errno -9985] Device unavailable

[ 2019-01-20 20:26:11 ] 
Traceback (most recent call last):
  File "alexa.py", line 55, in <module>
    detector.start(detected_callback=lambda: main.main(p,detector),sleep_time=0.03)
  File "/opt/MessyPi/yuyin/alexa/func_alexa/snowboydecoder.py", line 176, in start
    stream_callback=audio_callback)
  File "/usr/local/lib/python3.5/dist-packages/pyaudio.py", line 750, in open
    stream = Stream(self, *args, **kwargs)
  File "/usr/local/lib/python3.5/dist-packages/pyaudio.py", line 441, in __init__
    self._stream = pa.open(**arguments)
OSError: [Errno -9985] Device unavailable

[ 2019-01-20 20:29:35 ] 
Traceback (most recent call last):
  File "alexa.py", line 55, in <module>
    detector.start(detected_callback=lambda: main.main(p,detector),sleep_time=0.03)
  File "/opt/MessyPi/yuyin/alexa/func_alexa/snowboydecoder.py", line 176, in start
    stream_callback=audio_callback)
  File "/usr/local/lib/python3.5/dist-packages/pyaudio.py", line 750, in open
    stream = Stream(self, *args, **kwargs)
  File "/usr/local/lib/python3.5/dist-packages/pyaudio.py", line 441, in __init__
    self._stream = pa.open(**arguments)
OSError: [Errno -9985] Device unavailable

[ 2019-01-20 20:33:53 ] 
Traceback (most recent call last):
  File "alexa.py", line 55, in <module>
    detector.start(detected_callback=lambda: main.main(p,detector),sleep_time=0.03)
  File "/opt/MessyPi/yuyin/alexa/func_alexa/snowboydecoder.py", line 176, in start
    stream_callback=audio_callback)
  File "/usr/local/lib/python3.5/dist-packages/pyaudio.py", line 750, in open
    stream = Stream(self, *args, **kwargs)
  File "/usr/local/lib/python3.5/dist-packages/pyaudio.py", line 441, in __init__
    self._stream = pa.open(**arguments)
OSError: [Errno -9985] Device unavailable

[ 2019-01-20 21:13:55 ] 
Traceback (most recent call last):
  File "alexa.py", line 37, in <module>
    pygame.mixer.init(frequency=15500, size=-16, channels=4)
pygame.error: No available audio device

[ 2019-01-20 21:13:55 ] 
Traceback (most recent call last):
  File "alexa.py", line 37, in <module>
    pygame.mixer.init(frequency=15500, size=-16, channels=4)
pygame.error: No available audio device

During handling of the above exception, another exception occurred:

Traceback (most recent call last):
  File "alexa.py", line 42, in <module>
    exit()
  File "/usr/lib/python3.5/_sitebuiltins.py", line 26, in __call__
    raise SystemExit(code)
SystemExit: None

[ 2019-01-21 09:57:04 ] 
Traceback (most recent call last):
  File "alexa.py", line 37, in <module>
    pygame.mixer.init(frequency=15500, size=-16, channels=4)
pygame.error: No available audio device

[ 2020-06-17 09:48:17 ] 
Traceback (most recent call last):
  File "alexa.py", line 53, in <module>
    detector.start(detected_callback=lambda: main.main(p,detector),sleep_time=0.03)
  File "/home/pi/alexa/func_alexa/snowboydecoder.py", line 229, in start
    callback()
  File "alexa.py", line 53, in <lambda>
    detector.start(detected_callback=lambda: main.main(p,detector),sleep_time=0.03)
  File "/home/pi/alexa/func_messy/main.py", line 77, in main
    volume.play_prompt(alexa_said)
  File "/home/pi/alexa/func_messy/volume.py", line 100, in play_prompt
    pygame.mixer.music.load(file)
pygame.error: Unknown WAVE format

[ 2020-06-17 09:51:37 ] 
Traceback (most recent call last):
  File "alexa.py", line 53, in <module>
    detector.start(detected_callback=lambda: main.main(p,detector),sleep_time=0.03)
  File "/home/pi/alexa/func_alexa/snowboydecoder.py", line 229, in start
    callback()
  File "alexa.py", line 53, in <lambda>
    detector.start(detected_callback=lambda: main.main(p,detector),sleep_time=0.03)
  File "/home/pi/alexa/func_messy/main.py", line 77, in main
    volume.play_prompt(alexa_said)
  File "/home/pi/alexa/func_messy/volume.py", line 100, in play_prompt
    pygame.mixer.music.load(file)
pygame.error: Unknown WAVE format

[ 2020-06-17 09:55:08 ] 
Traceback (most recent call last):
  File "alexa.py", line 53, in <module>
    detector.start(detected_callback=lambda: main.main(p,detector),sleep_time=0.03)
  File "/home/pi/alexa/func_alexa/snowboydecoder.py", line 229, in start
    callback()
  File "alexa.py", line 53, in <lambda>
    detector.start(detected_callback=lambda: main.main(p,detector),sleep_time=0.03)
  File "/home/pi/alexa/func_messy/main.py", line 77, in main
    volume.play_prompt(alexa_said)
  File "/home/pi/alexa/func_messy/volume.py", line 100, in play_prompt
    pygame.mixer.music.load(file)
pygame.error: Unknown WAVE format

[ 2020-06-17 10:03:13 ] 
语音识别发生了错误，以下是具体信息:
{'err_msg': 'recognition error.', 'err_no': 3307, 'sn': '563959056891592384635'}
[ 2020-06-17 16:32:53 ] 
Traceback (most recent call last):
  File "alexa.py", line 53, in <module>
    detector.start(detected_callback=lambda: main.main(p,detector),sleep_time=0.03)
  File "/home/pi/alexa/func_alexa/snowboydecoder.py", line 229, in start
    callback()
  File "alexa.py", line 53, in <lambda>
    detector.start(detected_callback=lambda: main.main(p,detector),sleep_time=0.03)
  File "/home/pi/alexa/func_messy/main.py", line 37, in main
    volume_in = volume.volume(p)
  File "/home/pi/alexa/func_messy/volume.py", line 50, in volume
    data = stream.read(CHUNK)
  File "/home/pi/.local/lib/python3.7/site-packages/pyaudio.py", line 608, in read
    return pa.read_stream(self._stream, num_frames, exception_on_overflow)
OSError: [Errno -9981] Input overflowed

[ 2020-06-17 16:36:41 ] 
Traceback (most recent call last):
  File "alexa.py", line 53, in <module>
    detector.start(detected_callback=lambda: main.main(p,detector),sleep_time=0.03)
  File "/home/pi/alexa/func_alexa/snowboydecoder.py", line 229, in start
    callback()
  File "alexa.py", line 53, in <lambda>
    detector.start(detected_callback=lambda: main.main(p,detector),sleep_time=0.03)
  File "/home/pi/alexa/func_messy/main.py", line 37, in main
    volume_in = volume.volume(p)
  File "/home/pi/alexa/func_messy/volume.py", line 50, in volume
    data = stream.read(CHUNK)
  File "/home/pi/.local/lib/python3.7/site-packages/pyaudio.py", line 608, in read
    return pa.read_stream(self._stream, num_frames, exception_on_overflow)
OSError: [Errno -9981] Input overflowed

[ 2020-06-17 16:43:10 ] 
Traceback (most recent call last):
  File "alexa.py", line 53, in <module>
    detector.start(detected_callback=lambda: main.main(p,detector),sleep_time=0.03)
  File "/home/pi/alexa/func_alexa/snowboydecoder.py", line 229, in start
    callback()
  File "alexa.py", line 53, in <lambda>
    detector.start(detected_callback=lambda: main.main(p,detector),sleep_time=0.03)
  File "/home/pi/alexa/func_messy/main.py", line 37, in main
    volume_in = volume.volume(p)
  File "/home/pi/alexa/func_messy/volume.py", line 50, in volume
    data = stream.read(CHUNK)
  File "/home/pi/.local/lib/python3.7/site-packages/pyaudio.py", line 608, in read
    return pa.read_stream(self._stream, num_frames, exception_on_overflow)
OSError: [Errno -9981] Input overflowed

[ 2020-06-17 16:46:25 ] 
Traceback (most recent call last):
  File "alexa.py", line 53, in <module>
    detector.start(detected_callback=lambda: main.main(p,detector),sleep_time=0.03)
  File "/home/pi/alexa/func_alexa/snowboydecoder.py", line 229, in start
    callback()
  File "alexa.py", line 53, in <lambda>
    detector.start(detected_callback=lambda: main.main(p,detector),sleep_time=0.03)
  File "/home/pi/alexa/func_messy/main.py", line 37, in main
    volume_in = volume.volume(p)
  File "/home/pi/alexa/func_messy/volume.py", line 50, in volume
    data = stream.read(CHUNK)
  File "/home/pi/.local/lib/python3.7/site-packages/pyaudio.py", line 608, in read
    return pa.read_stream(self._stream, num_frames, exception_on_overflow)
OSError: [Errno -9981] Input overflowed

[ 2020-06-17 16:53:27 ] 
Traceback (most recent call last):
  File "alexa.py", line 53, in <module>
    detector.start(detected_callback=lambda: main.main(p,detector),sleep_time=0.03)
  File "/home/pi/alexa/func_alexa/snowboydecoder.py", line 229, in start
    callback()
  File "alexa.py", line 53, in <lambda>
    detector.start(detected_callback=lambda: main.main(p,detector),sleep_time=0.03)
  File "/home/pi/alexa/func_messy/main.py", line 37, in main
    volume_in = volume.volume(p)
  File "/home/pi/alexa/func_messy/volume.py", line 50, in volume
    data = stream.read(CHUNK)
  File "/home/pi/.local/lib/python3.7/site-packages/pyaudio.py", line 608, in read
    return pa.read_stream(self._stream, num_frames, exception_on_overflow)
OSError: [Errno -9981] Input overflowed

[ 2020-06-17 16:58:54 ] 
Traceback (most recent call last):
  File "alexa.py", line 53, in <module>
    detector.start(detected_callback=lambda: main.main(p,detector),sleep_time=0.03)
  File "/home/pi/alexa/func_alexa/snowboydecoder.py", line 229, in start
    callback()
  File "alexa.py", line 53, in <lambda>
    detector.start(detected_callback=lambda: main.main(p,detector),sleep_time=0.03)
  File "/home/pi/alexa/func_messy/main.py", line 37, in main
    volume_in = volume.volume(p)
  File "/home/pi/alexa/func_messy/volume.py", line 50, in volume
    data = stream.read(CHUNK,CHUNK, exception_on_overflow = False)
TypeError: read() got multiple values for argument 'exception_on_overflow'

[ 2020-06-18 01:22:59 ] 
Traceback (most recent call last):
  File "alexa.py", line 53, in <module>
    detector.start(detected_callback=lambda: main.main(p,detector),sleep_time=0.03)
  File "/home/pi/alexa/func_alexa/snowboydecoder.py", line 229, in start
    callback()
  File "alexa.py", line 53, in <lambda>
    detector.start(detected_callback=lambda: main.main(p,detector),sleep_time=0.03)
  File "/home/pi/alexa/func_messy/main.py", line 37, in main
    volume_in = volume.volume(p)
  File "/home/pi/alexa/func_messy/volume.py", line 50, in volume
    data = stream.read(CHUNK)
  File "/home/pi/.local/lib/python3.7/site-packages/pyaudio.py", line 608, in read
    return pa.read_stream(self._stream, num_frames, exception_on_overflow)
OSError: [Errno -9981] Input overflowed

[ 2020-06-18 02:15:44 ] 
语音识别发生了错误，以下是具体信息:
{'err_msg': 'recognition error.', 'err_no': 3307, 'sn': '78311952881592443003'}
[ 2020-06-18 02:15:44 ] 
语音识别发生了错误，以下是具体信息:
{'err_msg': 'recognition error.', 'err_no': 3307, 'sn': '185593383761592443132'}
[ 2020-06-18 02:15:44 ] 
语音识别发生了错误，以下是具体信息:
{'err_msg': 'recognition error.', 'err_no': 3307, 'sn': '909375974281592443218'}
[ 2020-06-18 02:15:44 ] 
语音识别发生了错误，以下是具体信息:
{'err_msg': 'recognition error.', 'err_no': 3307, 'sn': '134535356931592443242'}
[ 2020-06-18 02:15:44 ] 
语音识别发生了错误，以下是具体信息:
{'err_msg': 'recognition error.', 'err_no': 3307, 'sn': '439921732831592443271'}
[ 2020-06-18 02:26:21 ] 
语音识别发生了错误，以下是具体信息:
{'err_msg': 'recognition error.', 'err_no': 3307, 'sn': '486427811411592443598'}
[ 2020-06-18 02:26:21 ] 
Traceback (most recent call last):
  File "alexa.py", line 53, in <module>
    detector.start(detected_callback=lambda: main.main(p,detector),sleep_time=0.03)
  File "/home/pi/alexa/func_alexa/snowboydecoder.py", line 229, in start
    callback()
  File "alexa.py", line 53, in <lambda>
    detector.start(detected_callback=lambda: main.main(p,detector),sleep_time=0.03)
  File "/home/pi/alexa/func_messy/main.py", line 65, in main
    hecheng_keyword = isKeyword.main_2(i_said_text)
  File "/home/pi/alexa/func_messy/isKeyword.py", line 42, in main_2
    volume.play_prompt(hecheng_music)
  File "/home/pi/alexa/func_messy/volume.py", line 101, in play_prompt
    pygame.mixer.music.load(file)
pygame.error: Unknown WAVE format

[ 2020-06-18 02:44:16 ] 
Traceback (most recent call last):
  File "alexa.py", line 53, in <module>
    detector.start(detected_callback=lambda: main.main(p,detector),sleep_time=0.03)
  File "/home/pi/alexa/func_alexa/snowboydecoder.py", line 229, in start
    callback()
  File "alexa.py", line 53, in <lambda>
    detector.start(detected_callback=lambda: main.main(p,detector),sleep_time=0.03)
  File "/home/pi/alexa/func_messy/main.py", line 62, in main
    keyword = isKeyword.main_1(i_said_text)
  File "/home/pi/alexa/func_messy/isKeyword.py", line 23, in main_1
    eval(keywords[i])
  File "<string>", line 1, in <module>
  File "/home/pi/alexa/func_messy/household.py", line 32, in light_on
    led(20).on()
NameError: name 'led' is not defined

[ 2020-06-18 03:47:06 ] 
Traceback (most recent call last):
  File "alexa.py", line 53, in <module>
    detector.start(detected_callback=lambda: main.main(p,detector),sleep_time=0.03)
  File "/home/pi/alexa/func_alexa/snowboydecoder.py", line 229, in start
    callback()
  File "alexa.py", line 53, in <lambda>
    detector.start(detected_callback=lambda: main.main(p,detector),sleep_time=0.03)
  File "/home/pi/alexa/func_messy/main.py", line 62, in main
    keyword = isKeyword.main_1(i_said_text)
  File "/home/pi/alexa/func_messy/isKeyword.py", line 23, in main_1
    eval(keywords[i])
  File "<string>", line 1, in <module>
  File "/home/pi/alexa/func_messy/household.py", line 33, in light_on
    GPIO.output(23, 1)
RuntimeError: Please set pin numbering mode using GPIO.setmode(GPIO.BOARD) or GPIO.setmode(GPIO.BCM)

[ 2020-06-18 04:22:23 ] 
语音识别发生了错误，以下是具体信息:
{'err_msg': 'recognition error.', 'err_no': 3307, 'sn': '691907318201592450556'}
[ 2020-06-18 07:13:40 ] 
语音识别发生了错误，以下是具体信息:
{'err_msg': 'recognition error.', 'err_no': 3307, 'sn': '966678265061592460907'}
[ 2020-06-18 07:40:26 ] 
语音识别发生了错误，以下是具体信息:
{'err_msg': 'recognition error.', 'err_no': 3307, 'sn': '545318566451592462437'}
[ 2020-06-18 07:40:26 ] 
语音识别发生了错误，以下是具体信息:
{'err_msg': 'recognition error.', 'err_no': 3307, 'sn': '219668283951592463901'}
[ 2020-06-18 11:55:25 ] 
语音识别发生了错误，以下是具体信息:
{'err_msg': 'recognition error.', 'err_no': 3307, 'sn': '545464116651592477846'}
[ 2020-06-18 11:55:25 ] 
语音识别发生了错误，以下是具体信息:
{'err_msg': 'recognition error.', 'err_no': 3307, 'sn': '342796346441592478074'}
[ 2020-06-18 12:05:48 ] 
语音识别发生了错误，以下是具体信息:
{'err_msg': 'recognition error.', 'err_no': 3307, 'sn': '665802995141592478363'}
[ 2020-06-18 12:11:34 ] 
语音识别发生了错误，以下是具体信息:
{'err_msg': 'recognition error.', 'err_no': 3307, 'sn': '947444418021592478786'}
[ 2020-06-18 12:58:14 ] 
语音识别发生了错误，以下是具体信息:
{'err_msg': 'recognition error.', 'err_no': 3307, 'sn': '9799926421592481578'}
[ 2020-06-18 13:00:52 ] 
语音识别发生了错误，以下是具体信息:
{'err_msg': 'recognition error.', 'err_no': 3307, 'sn': '608551124431592481668'}
[ 2020-06-18 13:09:16 ] 
语音识别发生了错误，以下是具体信息:
{'err_msg': 'recognition error.', 'err_no': 3307, 'sn': '664513372141592482507'}
[ 2020-06-18 13:20:31 ] 
语音识别发生了错误，以下是具体信息:
{'err_msg': 'recognition error.', 'err_no': 3307, 'sn': '426718429291592482995'}
[ 2020-06-18 13:39:05 ] 
语音识别发生了错误，以下是具体信息:
{'err_msg': 'recognition error.', 'err_no': 3307, 'sn': '863381264531592484004'}
[ 2020-06-18 13:39:05 ] 
语音识别发生了错误，以下是具体信息:
{'err_msg': 'recognition error.', 'err_no': 3307, 'sn': '16873322501592484478'}
[ 2020-06-18 13:39:05 ] 
语音识别发生了错误，以下是具体信息:
{'err_msg': 'recognition error.', 'err_no': 3307, 'sn': '509426005701592484553'}
[ 2020-06-18 13:50:41 ] 
语音识别发生了错误，以下是具体信息:
{'err_msg': 'recognition error.', 'err_no': 3307, 'sn': '384969734911592484713'}
[ 2020-06-18 13:53:49 ] 
Traceback (most recent call last):
  File "/usr/lib/python3/dist-packages/urllib3/connection.py", line 159, in _new_conn
    (self._dns_host, self.port), self.timeout, **extra_kw)
  File "/usr/lib/python3/dist-packages/urllib3/util/connection.py", line 57, in create_connection
    for res in socket.getaddrinfo(host, port, family, socket.SOCK_STREAM):
  File "/usr/lib/python3.7/socket.py", line 748, in getaddrinfo
    for res in _socket.getaddrinfo(host, port, family, type, proto, flags):
socket.gaierror: [Errno -3] Temporary failure in name resolution

During handling of the above exception, another exception occurred:

Traceback (most recent call last):
  File "/usr/lib/python3/dist-packages/urllib3/connectionpool.py", line 600, in urlopen
    chunked=chunked)
  File "/usr/lib/python3/dist-packages/urllib3/connectionpool.py", line 354, in _make_request
    conn.request(method, url, **httplib_request_kw)
  File "/usr/lib/python3.7/http/client.py", line 1244, in request
    self._send_request(method, url, body, headers, encode_chunked)
  File "/usr/lib/python3.7/http/client.py", line 1290, in _send_request
    self.endheaders(body, encode_chunked=encode_chunked)
  File "/usr/lib/python3.7/http/client.py", line 1239, in endheaders
    self._send_output(message_body, encode_chunked=encode_chunked)
  File "/usr/lib/python3.7/http/client.py", line 1026, in _send_output
    self.send(msg)
  File "/usr/lib/python3.7/http/client.py", line 966, in send
    self.connect()
  File "/usr/lib/python3/dist-packages/urllib3/connection.py", line 181, in connect
    conn = self._new_conn()
  File "/usr/lib/python3/dist-packages/urllib3/connection.py", line 168, in _new_conn
    self, "Failed to establish a new connection: %s" % e)
urllib3.exceptions.NewConnectionError: <urllib3.connection.HTTPConnection object at 0xb2bc9df0>: Failed to establish a new connection: [Errno -3] Temporary failure in name resolution

During handling of the above exception, another exception occurred:

Traceback (most recent call last):
  File "/usr/lib/python3/dist-packages/requests/adapters.py", line 449, in send
    timeout=timeout
  File "/usr/lib/python3/dist-packages/urllib3/connectionpool.py", line 638, in urlopen
    _stacktrace=sys.exc_info()[2])
  File "/usr/lib/python3/dist-packages/urllib3/util/retry.py", line 398, in increment
    raise MaxRetryError(_pool, url, error or ResponseError(cause))
urllib3.exceptions.MaxRetryError: HTTPConnectionPool(host='vop.baidu.com', port=80): Max retries exceeded with url: /server_api (Caused by NewConnectionError('<urllib3.connection.HTTPConnection object at 0xb2bc9df0>: Failed to establish a new connection: [Errno -3] Temporary failure in name resolution'))

During handling of the above exception, another exception occurred:

Traceback (most recent call last):
  File "alexa.py", line 53, in <module>
    detector.start(detected_callback=lambda: main.main(p,detector),sleep_time=0.03)
  File "/home/pi/alexa/func_alexa/snowboydecoder.py", line 229, in start
    callback()
  File "alexa.py", line 53, in <lambda>
    detector.start(detected_callback=lambda: main.main(p,detector),sleep_time=0.03)
  File "/home/pi/alexa/func_messy/main.py", line 31, in main
    i_said_json = yuyinshibie.baidu(i_said)
  File "/home/pi/alexa/func_messy/yuyinshibie.py", line 20, in baidu
    result = client.asr(get_file_content(file), 'wav', 16000, {'lan': 'zh',})
  File "/home/pi/.local/lib/python3.7/site-packages/aip/speech.py", line 78, in asr
    return self._request(self.__asrUrl, data)
  File "/home/pi/.local/lib/python3.7/site-packages/aip/base.py", line 98, in _request
    ), proxies=self._proxies
  File "/usr/lib/python3/dist-packages/requests/api.py", line 116, in post
    return request('post', url, data=data, json=json, **kwargs)
  File "/usr/lib/python3/dist-packages/requests/api.py", line 60, in request
    return session.request(method=method, url=url, **kwargs)
  File "/usr/lib/python3/dist-packages/requests/sessions.py", line 533, in request
    resp = self.send(prep, **send_kwargs)
  File "/usr/lib/python3/dist-packages/requests/sessions.py", line 646, in send
    r = adapter.send(request, **kwargs)
  File "/usr/lib/python3/dist-packages/requests/adapters.py", line 516, in send
    raise ConnectionError(e, request=request)
requests.exceptions.ConnectionError: HTTPConnectionPool(host='vop.baidu.com', port=80): Max retries exceeded with url: /server_api (Caused by NewConnectionError('<urllib3.connection.HTTPConnection object at 0xb2bc9df0>: Failed to establish a new connection: [Errno -3] Temporary failure in name resolution'))

[ 2021-07-25 12:27:53 ] 
Traceback (most recent call last):
  File "alexa.py", line 43, in <module>
    model = sys.argv[1]
IndexError: list index out of range

[ 2021-07-25 12:27:53 ] 
Traceback (most recent call last):
  File "alexa.py", line 43, in <module>
    model = sys.argv[1]
IndexError: list index out of range

During handling of the above exception, another exception occurred:

Traceback (most recent call last):
  File "alexa.py", line 48, in <module>
    exit()
  File "/usr/lib/python3.7/_sitebuiltins.py", line 26, in __call__
    raise SystemExit(code)
SystemExit: None

[ 2021-07-25 12:35:07 ] 
Traceback (most recent call last):
  File "alexa.py", line 43, in <module>
    model = sys.argv[1]
IndexError: list index out of range

[ 2021-07-25 12:35:07 ] 
Traceback (most recent call last):
  File "alexa.py", line 43, in <module>
    model = sys.argv[1]
IndexError: list index out of range

During handling of the above exception, another exception occurred:

Traceback (most recent call last):
  File "alexa.py", line 48, in <module>
    exit()
  File "/usr/lib/python3.7/_sitebuiltins.py", line 26, in __call__
    raise SystemExit(code)
SystemExit: None

